<?xml version="1.0"?>
<robot name="scara_arm">

<!-- world link -->
<link name="world"/>

<!-- base_link and its fixed joint to the ground -->
<joint name="joint_fix" type="fixed">
  <parent link="world"/>
  <child link="base_link"/>
</joint>

<link name="base_link">
  <collision>
    <origin xyz="0 0 0.2" rpy="0 0 0"/>
    <geometry>
      <box size="0.2 0.2 0.4"/>
    </geometry>
  </collision>

  <visual>
    <origin xyz="0 0 0.2" rpy="0 0 0"/>
    <geometry>
      <box size="0.2 0.2 0.4"/>
    </geometry>
  </visual>

  <inertial>
    <origin xyz="0 0 0.2" rpy="0 0 0"/>
    <mass value="1"/>
    <inertia
      ixx="1.0" ixy="0.0" ixz="0.0"
      iyy="1.0" iyz="0.0"
      izz="1.0"/>
  </inertial>
</link>


<!-- revolute joint rotating along z axis -->
<joint name="rotation1" type="revolute">
  <parent link="base_link"/>
  <child link="arm1"/>
  <origin xyz="0 0 0.4" rpy="0 0 0"/>
  <axis xyz="0 0 1"/>
  <limit effort="100" velocity="100" lower="-2.6" upper="2.6"/>
</joint>

<link name="arm1">
  <collision>
    <origin xyz="0 0.5 0.05" rpy="0 0 0"/>
    <geometry>
      <box size="0.1 1.1 0.1"/>
    </geometry>
  </collision>

  <visual>
    <origin xyz="0 0.5 0.05" rpy="0 0 0"/>
    <geometry>
      <box size="0.1 1.1 0.1"/>
    </geometry>
  </visual>

  <inertial>
    <origin xyz="0 0 0.05" rpy="0 0 0"/>
    <mass value="1"/>
    <inertia
      ixx="0.001" ixy="0.0" ixz="0.0"
      iyy="0.001" iyz="0.0"
      izz="0.001"/>
  </inertial>
</link>

<gazebo reference="arm1">
  <material>Gazebo/Grey</material>
</gazebo>


<!-- revolute joint for elbow joint -->
<joint name="rotation2" type="revolute">
  <parent link="arm1"/>
  <child link="arm2"/>
  <origin xyz="0 1 0.1" rpy="0 0 0"/>
  <axis xyz="0 0 1"/>
  <limit effort="100" velocity="100" lower="-3.00" upper="3.00"/>
</joint>

<link name="arm2">
  <collision>
    <origin xyz="0 0.4 0.05" rpy="0 0 0"/>
    <geometry>
      <box size="0.1 0.9 0.1"/>
    </geometry>
  </collision>

  <visual>
    <origin xyz="0 0.4 0.05" rpy="0 0 0"/>
    <geometry>
      <box size="0.1 0.9 0.1"/>
    </geometry>
  </visual>

  <inertial>
    <origin xyz="0 0 0.05" rpy="0 0 0"/>
    <mass value="1"/>
    <inertia
      ixx="0.001" ixy="0.0" ixz="0.0"
      iyy="0.001" iyz="0.0"
      izz="0.001"/>
  </inertial>
</link>

<gazebo reference="arm2">
  <material>Gazebo/Grey</material>
</gazebo>

</robot>

